2022-05-27 23:30:09,197 ERROR: Exception on /most_useful [GET] [in c:\users\t\appdata\local\programs\python\python38-32\lib\site-packages\flask\app.py:1454]
Traceback (most recent call last):
  File "c:\users\t\appdata\local\programs\python\python38-32\lib\site-packages\flask\app.py", line 2070, in wsgi_app
    response = self.full_dispatch_request()
  File "c:\users\t\appdata\local\programs\python\python38-32\lib\site-packages\flask\app.py", line 1515, in full_dispatch_request
    rv = self.handle_user_exception(e)
  File "c:\users\t\appdata\local\programs\python\python38-32\lib\site-packages\flask\app.py", line 1513, in full_dispatch_request
    rv = self.dispatch_request()
  File "c:\users\t\appdata\local\programs\python\python38-32\lib\site-packages\flask\app.py", line 1499, in dispatch_request
    return self.ensure_sync(self.view_functions[rule.endpoint])(**req.view_args)
  File "c:\users\t\appdata\local\programs\python\python38-32\lib\site-packages\flask_login\utils.py", line 272, in decorated_view
    return func(*args, **kwargs)
  File "C:\Users\T\Desktop\flask-GoodBrowserGames\app\main\routes.py", line 236, in most_useful
    highrev = Review(body='', author='', stars='', game='',language='', useful='')
  File "<string>", line 4, in __init__
  File "c:\users\t\appdata\local\programs\python\python38-32\lib\site-packages\sqlalchemy\orm\state.py", line 480, in _initialize_instance
    manager.dispatch.init_failure(self, args, kwargs)
  File "c:\users\t\appdata\local\programs\python\python38-32\lib\site-packages\sqlalchemy\util\langhelpers.py", line 70, in __exit__
    compat.raise_(
  File "c:\users\t\appdata\local\programs\python\python38-32\lib\site-packages\sqlalchemy\util\compat.py", line 207, in raise_
    raise exception
  File "c:\users\t\appdata\local\programs\python\python38-32\lib\site-packages\sqlalchemy\orm\state.py", line 477, in _initialize_instance
    return manager.original_init(*mixed[1:], **kwargs)
  File "c:\users\t\appdata\local\programs\python\python38-32\lib\site-packages\sqlalchemy\orm\decl_base.py", line 1145, in _declarative_constructor
    setattr(self, k, kwargs[k])
  File "c:\users\t\appdata\local\programs\python\python38-32\lib\site-packages\sqlalchemy\orm\attributes.py", line 458, in __set__
    self.impl.set(
  File "c:\users\t\appdata\local\programs\python\python38-32\lib\site-packages\sqlalchemy\orm\attributes.py", line 1226, in set
    value = self.fire_replace_event(state, dict_, value, old, initiator)
  File "c:\users\t\appdata\local\programs\python\python38-32\lib\site-packages\sqlalchemy\orm\attributes.py", line 1248, in fire_replace_event
    value = fn(
  File "c:\users\t\appdata\local\programs\python\python38-32\lib\site-packages\sqlalchemy\orm\attributes.py", line 1683, in emit_backref_from_scalar_set_event
    instance_state(child),
AttributeError: 'str' object has no attribute '_sa_instance_state'
2022-05-27 23:33:54,140 ERROR: Exception on /most_useful [GET] [in c:\users\t\appdata\local\programs\python\python38-32\lib\site-packages\flask\app.py:1454]
Traceback (most recent call last):
  File "c:\users\t\appdata\local\programs\python\python38-32\lib\site-packages\flask\app.py", line 2070, in wsgi_app
    response = self.full_dispatch_request()
  File "c:\users\t\appdata\local\programs\python\python38-32\lib\site-packages\flask\app.py", line 1515, in full_dispatch_request
    rv = self.handle_user_exception(e)
  File "c:\users\t\appdata\local\programs\python\python38-32\lib\site-packages\flask\app.py", line 1513, in full_dispatch_request
    rv = self.dispatch_request()
  File "c:\users\t\appdata\local\programs\python\python38-32\lib\site-packages\flask\app.py", line 1499, in dispatch_request
    return self.ensure_sync(self.view_functions[rule.endpoint])(**req.view_args)
  File "c:\users\t\appdata\local\programs\python\python38-32\lib\site-packages\flask_login\utils.py", line 272, in decorated_view
    return func(*args, **kwargs)
  File "C:\Users\T\Desktop\flask-GoodBrowserGames\app\main\routes.py", line 236, in most_useful
    highrev = Review(body='', author='', stars='', game='',language='', useful='')
  File "<string>", line 4, in __init__
  File "c:\users\t\appdata\local\programs\python\python38-32\lib\site-packages\sqlalchemy\orm\state.py", line 480, in _initialize_instance
    manager.dispatch.init_failure(self, args, kwargs)
  File "c:\users\t\appdata\local\programs\python\python38-32\lib\site-packages\sqlalchemy\util\langhelpers.py", line 70, in __exit__
    compat.raise_(
  File "c:\users\t\appdata\local\programs\python\python38-32\lib\site-packages\sqlalchemy\util\compat.py", line 207, in raise_
    raise exception
  File "c:\users\t\appdata\local\programs\python\python38-32\lib\site-packages\sqlalchemy\orm\state.py", line 477, in _initialize_instance
    return manager.original_init(*mixed[1:], **kwargs)
  File "c:\users\t\appdata\local\programs\python\python38-32\lib\site-packages\sqlalchemy\orm\decl_base.py", line 1145, in _declarative_constructor
    setattr(self, k, kwargs[k])
  File "c:\users\t\appdata\local\programs\python\python38-32\lib\site-packages\sqlalchemy\orm\attributes.py", line 458, in __set__
    self.impl.set(
  File "c:\users\t\appdata\local\programs\python\python38-32\lib\site-packages\sqlalchemy\orm\attributes.py", line 1226, in set
    value = self.fire_replace_event(state, dict_, value, old, initiator)
  File "c:\users\t\appdata\local\programs\python\python38-32\lib\site-packages\sqlalchemy\orm\attributes.py", line 1248, in fire_replace_event
    value = fn(
  File "c:\users\t\appdata\local\programs\python\python38-32\lib\site-packages\sqlalchemy\orm\attributes.py", line 1683, in emit_backref_from_scalar_set_event
    instance_state(child),
AttributeError: 'str' object has no attribute '_sa_instance_state'
2022-05-27 23:34:56,574 INFO: GoodBrowserGames startup [in C:\Users\T\Desktop\flask-GoodBrowserGames\app\__init__.py:82]
2022-05-27 23:34:58,591 ERROR: Exception on /most_useful [GET] [in c:\users\t\appdata\local\programs\python\python38-32\lib\site-packages\flask\app.py:1454]
Traceback (most recent call last):
  File "c:\users\t\appdata\local\programs\python\python38-32\lib\site-packages\flask\app.py", line 2070, in wsgi_app
    response = self.full_dispatch_request()
  File "c:\users\t\appdata\local\programs\python\python38-32\lib\site-packages\flask\app.py", line 1515, in full_dispatch_request
    rv = self.handle_user_exception(e)
  File "c:\users\t\appdata\local\programs\python\python38-32\lib\site-packages\flask\app.py", line 1513, in full_dispatch_request
    rv = self.dispatch_request()
  File "c:\users\t\appdata\local\programs\python\python38-32\lib\site-packages\flask\app.py", line 1499, in dispatch_request
    return self.ensure_sync(self.view_functions[rule.endpoint])(**req.view_args)
  File "c:\users\t\appdata\local\programs\python\python38-32\lib\site-packages\flask_login\utils.py", line 272, in decorated_view
    return func(*args, **kwargs)
  File "C:\Users\T\Desktop\flask-GoodBrowserGames\app\main\routes.py", line 236, in most_useful
    highrev = Review(body='', author='', stars='', game='',language='', useful='')
  File "<string>", line 4, in __init__
  File "c:\users\t\appdata\local\programs\python\python38-32\lib\site-packages\sqlalchemy\orm\state.py", line 480, in _initialize_instance
    manager.dispatch.init_failure(self, args, kwargs)
  File "c:\users\t\appdata\local\programs\python\python38-32\lib\site-packages\sqlalchemy\util\langhelpers.py", line 70, in __exit__
    compat.raise_(
  File "c:\users\t\appdata\local\programs\python\python38-32\lib\site-packages\sqlalchemy\util\compat.py", line 207, in raise_
    raise exception
  File "c:\users\t\appdata\local\programs\python\python38-32\lib\site-packages\sqlalchemy\orm\state.py", line 477, in _initialize_instance
    return manager.original_init(*mixed[1:], **kwargs)
  File "c:\users\t\appdata\local\programs\python\python38-32\lib\site-packages\sqlalchemy\orm\decl_base.py", line 1145, in _declarative_constructor
    setattr(self, k, kwargs[k])
  File "c:\users\t\appdata\local\programs\python\python38-32\lib\site-packages\sqlalchemy\orm\attributes.py", line 458, in __set__
    self.impl.set(
  File "c:\users\t\appdata\local\programs\python\python38-32\lib\site-packages\sqlalchemy\orm\attributes.py", line 1226, in set
    value = self.fire_replace_event(state, dict_, value, old, initiator)
  File "c:\users\t\appdata\local\programs\python\python38-32\lib\site-packages\sqlalchemy\orm\attributes.py", line 1248, in fire_replace_event
    value = fn(
  File "c:\users\t\appdata\local\programs\python\python38-32\lib\site-packages\sqlalchemy\orm\attributes.py", line 1683, in emit_backref_from_scalar_set_event
    instance_state(child),
AttributeError: 'str' object has no attribute '_sa_instance_state'
2022-05-27 23:35:39,602 INFO: GoodBrowserGames startup [in C:\Users\T\Desktop\flask-GoodBrowserGames\app\__init__.py:82]
