2022-06-04 02:23:07,518 ERROR: Exception on /recommendation [GET] [in c:\users\t\appdata\local\programs\python\python38-32\lib\site-packages\flask\app.py:1454]
Traceback (most recent call last):
  File "c:\users\t\appdata\local\programs\python\python38-32\lib\site-packages\sqlalchemy\sql\elements.py", line 798, in __getattr__
    return getattr(self.comparator, key)
AttributeError: 'Comparator' object has no attribute 'count'

The above exception was the direct cause of the following exception:

Traceback (most recent call last):
  File "c:\users\t\appdata\local\programs\python\python38-32\lib\site-packages\sqlalchemy\orm\attributes.py", line 326, in __getattr__
    return getattr(self.comparator, key)
  File "c:\users\t\appdata\local\programs\python\python38-32\lib\site-packages\sqlalchemy\util\langhelpers.py", line 1240, in __getattr__
    return self._fallback_getattr(key)
  File "c:\users\t\appdata\local\programs\python\python38-32\lib\site-packages\sqlalchemy\orm\properties.py", line 427, in _fallback_getattr
    return getattr(self.__clause_element__(), key)
  File "c:\users\t\appdata\local\programs\python\python38-32\lib\site-packages\sqlalchemy\sql\elements.py", line 800, in __getattr__
    util.raise_(
  File "c:\users\t\appdata\local\programs\python\python38-32\lib\site-packages\sqlalchemy\util\compat.py", line 207, in raise_
    raise exception
AttributeError: Neither 'AnnotatedColumn' object nor 'Comparator' object has an attribute 'count'

The above exception was the direct cause of the following exception:

Traceback (most recent call last):
  File "c:\users\t\appdata\local\programs\python\python38-32\lib\site-packages\flask\app.py", line 2070, in wsgi_app
    response = self.full_dispatch_request()
  File "c:\users\t\appdata\local\programs\python\python38-32\lib\site-packages\flask\app.py", line 1515, in full_dispatch_request
    rv = self.handle_user_exception(e)
  File "c:\users\t\appdata\local\programs\python\python38-32\lib\site-packages\flask\app.py", line 1513, in full_dispatch_request
    rv = self.dispatch_request()
  File "c:\users\t\appdata\local\programs\python\python38-32\lib\site-packages\flask\app.py", line 1499, in dispatch_request
    return self.ensure_sync(self.view_functions[rule.endpoint])(**req.view_args)
  File "c:\users\t\appdata\local\programs\python\python38-32\lib\site-packages\flask_login\utils.py", line 272, in decorated_view
    return func(*args, **kwargs)
  File "C:\Users\T\Desktop\flask-GoodBrowserGames\app\main\routes.py", line 268, in recommendation
    game_id = randint(0, Game.id.count())
  File "c:\users\t\appdata\local\programs\python\python38-32\lib\site-packages\sqlalchemy\orm\attributes.py", line 328, in __getattr__
    util.raise_(
  File "c:\users\t\appdata\local\programs\python\python38-32\lib\site-packages\sqlalchemy\util\compat.py", line 207, in raise_
    raise exception
AttributeError: Neither 'InstrumentedAttribute' object nor 'Comparator' object associated with Game.id has an attribute 'count'
2022-06-04 02:26:12,167 INFO: GoodBrowserGames startup [in C:\Users\T\Desktop\flask-GoodBrowserGames\app\__init__.py:82]
2022-06-04 02:26:21,295 ERROR: Exception on /recommendation [GET] [in c:\users\t\appdata\local\programs\python\python38-32\lib\site-packages\flask\app.py:1454]
Traceback (most recent call last):
  File "c:\users\t\appdata\local\programs\python\python38-32\lib\site-packages\flask\app.py", line 2070, in wsgi_app
    response = self.full_dispatch_request()
  File "c:\users\t\appdata\local\programs\python\python38-32\lib\site-packages\flask\app.py", line 1515, in full_dispatch_request
    rv = self.handle_user_exception(e)
  File "c:\users\t\appdata\local\programs\python\python38-32\lib\site-packages\flask\app.py", line 1513, in full_dispatch_request
    rv = self.dispatch_request()
  File "c:\users\t\appdata\local\programs\python\python38-32\lib\site-packages\flask\app.py", line 1499, in dispatch_request
    return self.ensure_sync(self.view_functions[rule.endpoint])(**req.view_args)
  File "c:\users\t\appdata\local\programs\python\python38-32\lib\site-packages\flask_login\utils.py", line 272, in decorated_view
    return func(*args, **kwargs)
  File "C:\Users\T\Desktop\flask-GoodBrowserGames\app\main\routes.py", line 268, in recommendation
    game_count = db.query(Game).count()
AttributeError: 'SQLAlchemy' object has no attribute 'query'
2022-06-04 02:27:24,179 INFO: GoodBrowserGames startup [in C:\Users\T\Desktop\flask-GoodBrowserGames\app\__init__.py:82]
2022-06-04 02:35:23,126 INFO: GoodBrowserGames startup [in C:\Users\T\Desktop\flask-GoodBrowserGames\app\__init__.py:82]
