2022-05-23 19:49:22,333 ERROR: Exception on /game/test [GET] [in c:\users\t\appdata\local\programs\python\python38-32\lib\site-packages\flask\app.py:1454]
Traceback (most recent call last):
  File "c:\users\t\appdata\local\programs\python\python38-32\lib\site-packages\flask\app.py", line 2070, in wsgi_app
    response = self.full_dispatch_request()
  File "c:\users\t\appdata\local\programs\python\python38-32\lib\site-packages\flask\app.py", line 1515, in full_dispatch_request
    rv = self.handle_user_exception(e)
  File "c:\users\t\appdata\local\programs\python\python38-32\lib\site-packages\flask\app.py", line 1513, in full_dispatch_request
    rv = self.dispatch_request()
  File "c:\users\t\appdata\local\programs\python\python38-32\lib\site-packages\flask\app.py", line 1499, in dispatch_request
    return self.ensure_sync(self.view_functions[rule.endpoint])(**req.view_args)
  File "c:\users\t\appdata\local\programs\python\python38-32\lib\site-packages\flask_login\utils.py", line 272, in decorated_view
    return func(*args, **kwargs)
  File "C:\Users\T\Desktop\flask-GoodBrowserGames\app\main\routes.py", line 198, in game
    return render_template('game.html', user=user, reviews=reviews.items,
  File "c:\users\t\appdata\local\programs\python\python38-32\lib\site-packages\flask\templating.py", line 147, in render_template
    return _render(
  File "c:\users\t\appdata\local\programs\python\python38-32\lib\site-packages\flask\templating.py", line 128, in _render
    rv = template.render(context)
  File "c:\users\t\appdata\local\programs\python\python38-32\lib\site-packages\jinja2\environment.py", line 1304, in render
    self.environment.handle_exception()
  File "c:\users\t\appdata\local\programs\python\python38-32\lib\site-packages\jinja2\environment.py", line 925, in handle_exception
    raise rewrite_traceback_stack(source=source)
  File "C:\Users\T\Desktop\flask-GoodBrowserGames\app\templates\game.html", line 1, in top-level template code
    {% extends "base.html" %}
  File "C:\Users\T\Desktop\flask-GoodBrowserGames\app\templates\base.html", line 1, in top-level template code
    {% extends 'bootstrap/base.html' %}
  File "c:\users\t\appdata\local\programs\python\python38-32\lib\site-packages\flask_bootstrap\templates\bootstrap\base.html", line 1, in top-level template code
    {% block doc -%}
  File "c:\users\t\appdata\local\programs\python\python38-32\lib\site-packages\flask_bootstrap\templates\bootstrap\base.html", line 4, in block 'doc'
    {%- block html %}
  File "c:\users\t\appdata\local\programs\python\python38-32\lib\site-packages\flask_bootstrap\templates\bootstrap\base.html", line 20, in block 'html'
    {% block body -%}
  File "c:\users\t\appdata\local\programs\python\python38-32\lib\site-packages\flask_bootstrap\templates\bootstrap\base.html", line 23, in block 'body'
    {% block content -%}
  File "C:\Users\T\Desktop\flask-GoodBrowserGames\app\templates\base.html", line 55, in block 'content'
    {% block app_content %}{% endblock %}
  File "C:\Users\T\Desktop\flask-GoodBrowserGames\app\templates\game.html", line 10, in block 'app_content'
    <form action="{{ url_for('main.game.review', name=game.name) }}" method="post">
  File "c:\users\t\appdata\local\programs\python\python38-32\lib\site-packages\flask\helpers.py", line 338, in url_for
    return appctx.app.handle_url_build_error(error, endpoint, values)
  File "c:\users\t\appdata\local\programs\python\python38-32\lib\site-packages\flask\helpers.py", line 325, in url_for
    rv = url_adapter.build(
  File "c:\users\t\appdata\local\programs\python\python38-32\lib\site-packages\werkzeug\routing.py", line 2305, in build
    raise BuildError(endpoint, values, method, self)
werkzeug.routing.BuildError: Could not build url for endpoint 'main.game.review' with values ['name']. Did you mean 'main.game' instead?
2022-05-23 19:56:39,127 ERROR: Exception on /game/test/review [GET] [in c:\users\t\appdata\local\programs\python\python38-32\lib\site-packages\flask\app.py:1454]
Traceback (most recent call last):
  File "c:\users\t\appdata\local\programs\python\python38-32\lib\site-packages\flask\app.py", line 2070, in wsgi_app
    response = self.full_dispatch_request()
  File "c:\users\t\appdata\local\programs\python\python38-32\lib\site-packages\flask\app.py", line 1515, in full_dispatch_request
    rv = self.handle_user_exception(e)
  File "c:\users\t\appdata\local\programs\python\python38-32\lib\site-packages\flask\app.py", line 1513, in full_dispatch_request
    rv = self.dispatch_request()
  File "c:\users\t\appdata\local\programs\python\python38-32\lib\site-packages\flask\app.py", line 1499, in dispatch_request
    return self.ensure_sync(self.view_functions[rule.endpoint])(**req.view_args)
  File "c:\users\t\appdata\local\programs\python\python38-32\lib\site-packages\flask_login\utils.py", line 272, in decorated_view
    return func(*args, **kwargs)
  File "C:\Users\T\Desktop\flask-GoodBrowserGames\app\main\routes.py", line 220, in review_game
    return render_template('create_review.html', title=_('Review'), form=form, review=review, name=name, language=language)
UnboundLocalError: local variable 'review' referenced before assignment
2022-05-23 19:56:48,876 INFO: GoodBrowserGames startup [in C:\Users\T\Desktop\flask-GoodBrowserGames\app\__init__.py:82]
2022-05-23 19:56:54,052 ERROR: Exception on /game/test [GET] [in c:\users\t\appdata\local\programs\python\python38-32\lib\site-packages\flask\app.py:1454]
Traceback (most recent call last):
  File "c:\users\t\appdata\local\programs\python\python38-32\lib\site-packages\flask\app.py", line 2070, in wsgi_app
    response = self.full_dispatch_request()
  File "c:\users\t\appdata\local\programs\python\python38-32\lib\site-packages\flask\app.py", line 1515, in full_dispatch_request
    rv = self.handle_user_exception(e)
  File "c:\users\t\appdata\local\programs\python\python38-32\lib\site-packages\flask\app.py", line 1513, in full_dispatch_request
    rv = self.dispatch_request()
  File "c:\users\t\appdata\local\programs\python\python38-32\lib\site-packages\flask\app.py", line 1499, in dispatch_request
    return self.ensure_sync(self.view_functions[rule.endpoint])(**req.view_args)
  File "c:\users\t\appdata\local\programs\python\python38-32\lib\site-packages\flask_login\utils.py", line 272, in decorated_view
    return func(*args, **kwargs)
  File "C:\Users\T\Desktop\flask-GoodBrowserGames\app\main\routes.py", line 198, in game
    return render_template('game.html', user=user, reviews=reviews.items,
  File "c:\users\t\appdata\local\programs\python\python38-32\lib\site-packages\flask\templating.py", line 147, in render_template
    return _render(
  File "c:\users\t\appdata\local\programs\python\python38-32\lib\site-packages\flask\templating.py", line 128, in _render
    rv = template.render(context)
  File "c:\users\t\appdata\local\programs\python\python38-32\lib\site-packages\jinja2\environment.py", line 1304, in render
    self.environment.handle_exception()
  File "c:\users\t\appdata\local\programs\python\python38-32\lib\site-packages\jinja2\environment.py", line 925, in handle_exception
    raise rewrite_traceback_stack(source=source)
  File "C:\Users\T\Desktop\flask-GoodBrowserGames\app\templates\game.html", line 1, in top-level template code
    {% extends "base.html" %}
  File "C:\Users\T\Desktop\flask-GoodBrowserGames\app\templates\base.html", line 1, in top-level template code
    {% extends 'bootstrap/base.html' %}
  File "c:\users\t\appdata\local\programs\python\python38-32\lib\site-packages\flask_bootstrap\templates\bootstrap\base.html", line 1, in top-level template code
    {% block doc -%}
  File "c:\users\t\appdata\local\programs\python\python38-32\lib\site-packages\flask_bootstrap\templates\bootstrap\base.html", line 4, in block 'doc'
    {%- block html %}
  File "c:\users\t\appdata\local\programs\python\python38-32\lib\site-packages\flask_bootstrap\templates\bootstrap\base.html", line 20, in block 'html'
    {% block body -%}
  File "c:\users\t\appdata\local\programs\python\python38-32\lib\site-packages\flask_bootstrap\templates\bootstrap\base.html", line 23, in block 'body'
    {% block content -%}
  File "C:\Users\T\Desktop\flask-GoodBrowserGames\app\templates\base.html", line 55, in block 'content'
    {% block app_content %}{% endblock %}
  File "C:\Users\T\Desktop\flask-GoodBrowserGames\app\templates\game.html", line 10, in block 'app_content'
    <form action="{{ url_for('main.game.create_review', name=game.name) }}" method="post">
  File "c:\users\t\appdata\local\programs\python\python38-32\lib\site-packages\flask\helpers.py", line 338, in url_for
    return appctx.app.handle_url_build_error(error, endpoint, values)
  File "c:\users\t\appdata\local\programs\python\python38-32\lib\site-packages\flask\helpers.py", line 325, in url_for
    rv = url_adapter.build(
  File "c:\users\t\appdata\local\programs\python\python38-32\lib\site-packages\werkzeug\routing.py", line 2305, in build
    raise BuildError(endpoint, values, method, self)
werkzeug.routing.BuildError: Could not build url for endpoint 'main.game.create_review' with values ['name']. Did you mean 'main.create_game' instead?
2022-05-23 20:00:32,316 INFO: GoodBrowserGames startup [in C:\Users\T\Desktop\flask-GoodBrowserGames\app\__init__.py:82]
