2022-06-04 00:39:36,861 ERROR: Exception on /index [GET] [in c:\users\t\appdata\local\programs\python\python38-32\lib\site-packages\flask\app.py:1454]
Traceback (most recent call last):
  File "c:\users\t\appdata\local\programs\python\python38-32\lib\site-packages\flask\app.py", line 2070, in wsgi_app
    response = self.full_dispatch_request()
  File "c:\users\t\appdata\local\programs\python\python38-32\lib\site-packages\flask\app.py", line 1515, in full_dispatch_request
    rv = self.handle_user_exception(e)
  File "c:\users\t\appdata\local\programs\python\python38-32\lib\site-packages\flask\app.py", line 1513, in full_dispatch_request
    rv = self.dispatch_request()
  File "c:\users\t\appdata\local\programs\python\python38-32\lib\site-packages\flask\app.py", line 1499, in dispatch_request
    return self.ensure_sync(self.view_functions[rule.endpoint])(**req.view_args)
  File "c:\users\t\appdata\local\programs\python\python38-32\lib\site-packages\flask_login\utils.py", line 272, in decorated_view
    return func(*args, **kwargs)
  File "C:\Users\T\Desktop\flask-GoodBrowserGames\app\main\routes.py", line 47, in index
    return render_template('index.html', title=_('Home'), form=form,
  File "c:\users\t\appdata\local\programs\python\python38-32\lib\site-packages\flask\templating.py", line 147, in render_template
    return _render(
  File "c:\users\t\appdata\local\programs\python\python38-32\lib\site-packages\flask\templating.py", line 128, in _render
    rv = template.render(context)
  File "c:\users\t\appdata\local\programs\python\python38-32\lib\site-packages\jinja2\environment.py", line 1304, in render
    self.environment.handle_exception()
  File "c:\users\t\appdata\local\programs\python\python38-32\lib\site-packages\jinja2\environment.py", line 925, in handle_exception
    raise rewrite_traceback_stack(source=source)
  File "C:\Users\T\Desktop\flask-GoodBrowserGames\app\templates\index.html", line 2, in top-level template code
    {% import 'bootstrap/wtf.html' as wtf %}
  File "C:\Users\T\Desktop\flask-GoodBrowserGames\app\templates\base.html", line 1, in top-level template code
    {% extends 'bootstrap/base.html' %}
  File "c:\users\t\appdata\local\programs\python\python38-32\lib\site-packages\flask_bootstrap\templates\bootstrap\base.html", line 1, in top-level template code
    {% block doc -%}
  File "c:\users\t\appdata\local\programs\python\python38-32\lib\site-packages\flask_bootstrap\templates\bootstrap\base.html", line 4, in block 'doc'
    {%- block html %}
  File "c:\users\t\appdata\local\programs\python\python38-32\lib\site-packages\flask_bootstrap\templates\bootstrap\base.html", line 20, in block 'html'
    {% block body -%}
  File "c:\users\t\appdata\local\programs\python\python38-32\lib\site-packages\flask_bootstrap\templates\bootstrap\base.html", line 23, in block 'body'
    {% block content -%}
  File "C:\Users\T\Desktop\flask-GoodBrowserGames\app\templates\base.html", line 56, in block 'content'
    {% block app_content %}{% endblock %}
  File "C:\Users\T\Desktop\flask-GoodBrowserGames\app\templates\index.html", line 17, in block 'app_content'
    {% include '_post.html' %}
  File "C:\Users\T\Desktop\flask-GoodBrowserGames\app\templates\_post.html", line 4, in top-level template code
    <a href="{{ url_for('main.user', username=post.author.username) }}">
  File "c:\users\t\appdata\local\programs\python\python38-32\lib\site-packages\jinja2\environment.py", line 474, in getattr
    return getattr(obj, attribute)
jinja2.exceptions.UndefinedError: 'app.models.Post object' has no attribute 'author'
2022-06-04 01:00:00,222 INFO: GoodBrowserGames startup [in C:\Users\T\Desktop\flask-GoodBrowserGames\app\__init__.py:82]
2022-06-04 01:00:06,667 INFO: GoodBrowserGames startup [in C:\Users\T\Desktop\flask-GoodBrowserGames\app\__init__.py:82]
2022-06-04 01:00:11,215 INFO: GoodBrowserGames startup [in C:\Users\T\Desktop\flask-GoodBrowserGames\app\__init__.py:82]
2022-06-04 01:00:14,812 INFO: GoodBrowserGames startup [in C:\Users\T\Desktop\flask-GoodBrowserGames\app\__init__.py:82]
2022-06-04 01:34:51,438 INFO: GoodBrowserGames startup [in C:\Users\T\Desktop\flask-GoodBrowserGames\app\__init__.py:82]
2022-06-04 01:46:23,728 ERROR: Exception on /game/Castaway 2 [POST] [in c:\users\t\appdata\local\programs\python\python38-32\lib\site-packages\flask\app.py:1454]
Traceback (most recent call last):
  File "c:\users\t\appdata\local\programs\python\python38-32\lib\site-packages\flask\app.py", line 2070, in wsgi_app
    response = self.full_dispatch_request()
  File "c:\users\t\appdata\local\programs\python\python38-32\lib\site-packages\flask\app.py", line 1515, in full_dispatch_request
    rv = self.handle_user_exception(e)
  File "c:\users\t\appdata\local\programs\python\python38-32\lib\site-packages\flask\app.py", line 1513, in full_dispatch_request
    rv = self.dispatch_request()
  File "c:\users\t\appdata\local\programs\python\python38-32\lib\site-packages\flask\app.py", line 1499, in dispatch_request
    return self.ensure_sync(self.view_functions[rule.endpoint])(**req.view_args)
  File "c:\users\t\appdata\local\programs\python\python38-32\lib\site-packages\flask_login\utils.py", line 272, in decorated_view
    return func(*args, **kwargs)
  File "C:\Users\T\Desktop\flask-GoodBrowserGames\app\main\routes.py", line 201, in game
    review = Review(body=form.review.data, author=current_user, stars=form.stars.data, game=game,
  File "<string>", line 4, in __init__
  File "c:\users\t\appdata\local\programs\python\python38-32\lib\site-packages\sqlalchemy\orm\state.py", line 480, in _initialize_instance
    manager.dispatch.init_failure(self, args, kwargs)
  File "c:\users\t\appdata\local\programs\python\python38-32\lib\site-packages\sqlalchemy\util\langhelpers.py", line 70, in __exit__
    compat.raise_(
  File "c:\users\t\appdata\local\programs\python\python38-32\lib\site-packages\sqlalchemy\util\compat.py", line 207, in raise_
    raise exception
  File "c:\users\t\appdata\local\programs\python\python38-32\lib\site-packages\sqlalchemy\orm\state.py", line 477, in _initialize_instance
    return manager.original_init(*mixed[1:], **kwargs)
  File "c:\users\t\appdata\local\programs\python\python38-32\lib\site-packages\sqlalchemy\orm\decl_base.py", line 1142, in _declarative_constructor
    raise TypeError(
TypeError: 'author' is an invalid keyword argument for Review
2022-06-04 01:51:27,398 INFO: GoodBrowserGames startup [in C:\Users\T\Desktop\flask-GoodBrowserGames\app\__init__.py:82]
2022-06-04 01:51:29,365 ERROR: Exception on /game/Castaway 2 [POST] [in c:\users\t\appdata\local\programs\python\python38-32\lib\site-packages\flask\app.py:1454]
Traceback (most recent call last):
  File "c:\users\t\appdata\local\programs\python\python38-32\lib\site-packages\flask\app.py", line 2070, in wsgi_app
    response = self.full_dispatch_request()
  File "c:\users\t\appdata\local\programs\python\python38-32\lib\site-packages\flask\app.py", line 1515, in full_dispatch_request
    rv = self.handle_user_exception(e)
  File "c:\users\t\appdata\local\programs\python\python38-32\lib\site-packages\flask\app.py", line 1513, in full_dispatch_request
    rv = self.dispatch_request()
  File "c:\users\t\appdata\local\programs\python\python38-32\lib\site-packages\flask\app.py", line 1499, in dispatch_request
    return self.ensure_sync(self.view_functions[rule.endpoint])(**req.view_args)
  File "c:\users\t\appdata\local\programs\python\python38-32\lib\site-packages\flask_login\utils.py", line 272, in decorated_view
    return func(*args, **kwargs)
  File "C:\Users\T\Desktop\flask-GoodBrowserGames\app\main\routes.py", line 201, in game
    review = Review(body=form.review.data, author=current_user, stars=form.stars.data, game=game,
  File "<string>", line 4, in __init__
  File "c:\users\t\appdata\local\programs\python\python38-32\lib\site-packages\sqlalchemy\orm\state.py", line 480, in _initialize_instance
    manager.dispatch.init_failure(self, args, kwargs)
  File "c:\users\t\appdata\local\programs\python\python38-32\lib\site-packages\sqlalchemy\util\langhelpers.py", line 70, in __exit__
    compat.raise_(
  File "c:\users\t\appdata\local\programs\python\python38-32\lib\site-packages\sqlalchemy\util\compat.py", line 207, in raise_
    raise exception
  File "c:\users\t\appdata\local\programs\python\python38-32\lib\site-packages\sqlalchemy\orm\state.py", line 477, in _initialize_instance
    return manager.original_init(*mixed[1:], **kwargs)
  File "c:\users\t\appdata\local\programs\python\python38-32\lib\site-packages\sqlalchemy\orm\decl_base.py", line 1145, in _declarative_constructor
    setattr(self, k, kwargs[k])
  File "c:\users\t\appdata\local\programs\python\python38-32\lib\site-packages\sqlalchemy\orm\attributes.py", line 458, in __set__
    self.impl.set(
  File "c:\users\t\appdata\local\programs\python\python38-32\lib\site-packages\sqlalchemy\orm\dynamic.py", line 183, in set
    new_values = list(iterable)
TypeError: 'User' object is not iterable
