2022-06-04 02:08:29,196 ERROR: Exception on /game/Castaway 2 [POST] [in c:\users\t\appdata\local\programs\python\python38-32\lib\site-packages\flask\app.py:1454]
Traceback (most recent call last):
  File "c:\users\t\appdata\local\programs\python\python38-32\lib\site-packages\flask\app.py", line 2070, in wsgi_app
    response = self.full_dispatch_request()
  File "c:\users\t\appdata\local\programs\python\python38-32\lib\site-packages\flask\app.py", line 1515, in full_dispatch_request
    rv = self.handle_user_exception(e)
  File "c:\users\t\appdata\local\programs\python\python38-32\lib\site-packages\flask\app.py", line 1513, in full_dispatch_request
    rv = self.dispatch_request()
  File "c:\users\t\appdata\local\programs\python\python38-32\lib\site-packages\flask\app.py", line 1499, in dispatch_request
    return self.ensure_sync(self.view_functions[rule.endpoint])(**req.view_args)
  File "c:\users\t\appdata\local\programs\python\python38-32\lib\site-packages\flask_login\utils.py", line 272, in decorated_view
    return func(*args, **kwargs)
  File "C:\Users\T\Desktop\flask-GoodBrowserGames\app\main\routes.py", line 201, in game
    review = Review(body=form.review.data, user_review=current_user.username, stars=form.stars.data, game=game,
  File "<string>", line 4, in __init__
  File "c:\users\t\appdata\local\programs\python\python38-32\lib\site-packages\sqlalchemy\orm\state.py", line 480, in _initialize_instance
    manager.dispatch.init_failure(self, args, kwargs)
  File "c:\users\t\appdata\local\programs\python\python38-32\lib\site-packages\sqlalchemy\util\langhelpers.py", line 70, in __exit__
    compat.raise_(
  File "c:\users\t\appdata\local\programs\python\python38-32\lib\site-packages\sqlalchemy\util\compat.py", line 207, in raise_
    raise exception
  File "c:\users\t\appdata\local\programs\python\python38-32\lib\site-packages\sqlalchemy\orm\state.py", line 477, in _initialize_instance
    return manager.original_init(*mixed[1:], **kwargs)
  File "c:\users\t\appdata\local\programs\python\python38-32\lib\site-packages\sqlalchemy\orm\decl_base.py", line 1145, in _declarative_constructor
    setattr(self, k, kwargs[k])
  File "c:\users\t\appdata\local\programs\python\python38-32\lib\site-packages\sqlalchemy\orm\attributes.py", line 458, in __set__
    self.impl.set(
  File "c:\users\t\appdata\local\programs\python\python38-32\lib\site-packages\sqlalchemy\orm\dynamic.py", line 202, in set
    self.fire_append_event(
  File "c:\users\t\appdata\local\programs\python\python38-32\lib\site-packages\sqlalchemy\orm\dynamic.py", line 134, in fire_append_event
    value = fn(state, value, initiator or self._append_token)
  File "c:\users\t\appdata\local\programs\python\python38-32\lib\site-packages\sqlalchemy\orm\attributes.py", line 1719, in emit_backref_from_collection_append_event
    child_state, child_dict = instance_state(child), instance_dict(child)
AttributeError: 'str' object has no attribute '_sa_instance_state'
2022-06-04 02:15:10,966 INFO: GoodBrowserGames startup [in C:\Users\T\Desktop\flask-GoodBrowserGames\app\__init__.py:82]
2022-06-04 02:15:48,554 INFO: GoodBrowserGames startup [in C:\Users\T\Desktop\flask-GoodBrowserGames\app\__init__.py:82]
2022-06-04 02:15:50,631 ERROR: Exception on /game/Castaway 2 [POST] [in c:\users\t\appdata\local\programs\python\python38-32\lib\site-packages\flask\app.py:1454]
Traceback (most recent call last):
  File "c:\users\t\appdata\local\programs\python\python38-32\lib\site-packages\flask\app.py", line 2070, in wsgi_app
    response = self.full_dispatch_request()
  File "c:\users\t\appdata\local\programs\python\python38-32\lib\site-packages\flask\app.py", line 1515, in full_dispatch_request
    rv = self.handle_user_exception(e)
  File "c:\users\t\appdata\local\programs\python\python38-32\lib\site-packages\flask\app.py", line 1513, in full_dispatch_request
    rv = self.dispatch_request()
  File "c:\users\t\appdata\local\programs\python\python38-32\lib\site-packages\flask\app.py", line 1499, in dispatch_request
    return self.ensure_sync(self.view_functions[rule.endpoint])(**req.view_args)
  File "c:\users\t\appdata\local\programs\python\python38-32\lib\site-packages\flask_login\utils.py", line 272, in decorated_view
    return func(*args, **kwargs)
  File "C:\Users\T\Desktop\flask-GoodBrowserGames\app\main\routes.py", line 201, in game
    review = Review(body=form.review.data, user_review=current_user, stars=form.stars.data, game=game,
  File "<string>", line 4, in __init__
  File "c:\users\t\appdata\local\programs\python\python38-32\lib\site-packages\sqlalchemy\orm\state.py", line 480, in _initialize_instance
    manager.dispatch.init_failure(self, args, kwargs)
  File "c:\users\t\appdata\local\programs\python\python38-32\lib\site-packages\sqlalchemy\util\langhelpers.py", line 70, in __exit__
    compat.raise_(
  File "c:\users\t\appdata\local\programs\python\python38-32\lib\site-packages\sqlalchemy\util\compat.py", line 207, in raise_
    raise exception
  File "c:\users\t\appdata\local\programs\python\python38-32\lib\site-packages\sqlalchemy\orm\state.py", line 477, in _initialize_instance
    return manager.original_init(*mixed[1:], **kwargs)
  File "c:\users\t\appdata\local\programs\python\python38-32\lib\site-packages\sqlalchemy\orm\decl_base.py", line 1142, in _declarative_constructor
    raise TypeError(
TypeError: 'user_review' is an invalid keyword argument for Review
2022-06-04 02:16:31,811 INFO: GoodBrowserGames startup [in C:\Users\T\Desktop\flask-GoodBrowserGames\app\__init__.py:82]
2022-06-04 02:16:36,073 ERROR: Exception on /game/Castaway 2 [POST] [in c:\users\t\appdata\local\programs\python\python38-32\lib\site-packages\flask\app.py:1454]
Traceback (most recent call last):
  File "c:\users\t\appdata\local\programs\python\python38-32\lib\site-packages\flask\app.py", line 2070, in wsgi_app
    response = self.full_dispatch_request()
  File "c:\users\t\appdata\local\programs\python\python38-32\lib\site-packages\flask\app.py", line 1515, in full_dispatch_request
    rv = self.handle_user_exception(e)
  File "c:\users\t\appdata\local\programs\python\python38-32\lib\site-packages\flask\app.py", line 1513, in full_dispatch_request
    rv = self.dispatch_request()
  File "c:\users\t\appdata\local\programs\python\python38-32\lib\site-packages\flask\app.py", line 1499, in dispatch_request
    return self.ensure_sync(self.view_functions[rule.endpoint])(**req.view_args)
  File "c:\users\t\appdata\local\programs\python\python38-32\lib\site-packages\flask_login\utils.py", line 272, in decorated_view
    return func(*args, **kwargs)
  File "C:\Users\T\Desktop\flask-GoodBrowserGames\app\main\routes.py", line 201, in game
    review = Review(body=form.review.data, author=current_user, stars=form.stars.data, game=game,
  File "<string>", line 4, in __init__
  File "c:\users\t\appdata\local\programs\python\python38-32\lib\site-packages\sqlalchemy\orm\state.py", line 480, in _initialize_instance
    manager.dispatch.init_failure(self, args, kwargs)
  File "c:\users\t\appdata\local\programs\python\python38-32\lib\site-packages\sqlalchemy\util\langhelpers.py", line 70, in __exit__
    compat.raise_(
  File "c:\users\t\appdata\local\programs\python\python38-32\lib\site-packages\sqlalchemy\util\compat.py", line 207, in raise_
    raise exception
  File "c:\users\t\appdata\local\programs\python\python38-32\lib\site-packages\sqlalchemy\orm\state.py", line 477, in _initialize_instance
    return manager.original_init(*mixed[1:], **kwargs)
  File "c:\users\t\appdata\local\programs\python\python38-32\lib\site-packages\sqlalchemy\orm\decl_base.py", line 1142, in _declarative_constructor
    raise TypeError(
TypeError: 'game' is an invalid keyword argument for Review
2022-06-04 02:18:38,897 INFO: GoodBrowserGames startup [in C:\Users\T\Desktop\flask-GoodBrowserGames\app\__init__.py:82]
