2022-05-24 22:26:35,556 ERROR: Exception on /game/test [GET] [in c:\users\t\appdata\local\programs\python\python38-32\lib\site-packages\flask\app.py:1454]
Traceback (most recent call last):
  File "c:\users\t\appdata\local\programs\python\python38-32\lib\site-packages\flask\app.py", line 2070, in wsgi_app
    response = self.full_dispatch_request()
  File "c:\users\t\appdata\local\programs\python\python38-32\lib\site-packages\flask\app.py", line 1515, in full_dispatch_request
    rv = self.handle_user_exception(e)
  File "c:\users\t\appdata\local\programs\python\python38-32\lib\site-packages\flask\app.py", line 1513, in full_dispatch_request
    rv = self.dispatch_request()
  File "c:\users\t\appdata\local\programs\python\python38-32\lib\site-packages\flask\app.py", line 1499, in dispatch_request
    return self.ensure_sync(self.view_functions[rule.endpoint])(**req.view_args)
  File "c:\users\t\appdata\local\programs\python\python38-32\lib\site-packages\flask_login\utils.py", line 272, in decorated_view
    return func(*args, **kwargs)
  File "C:\Users\T\Desktop\flask-GoodBrowserGames\app\main\routes.py", line 214, in game
    return render_template('game.html', user=user, reviews=reviews.items,
  File "c:\users\t\appdata\local\programs\python\python38-32\lib\site-packages\flask\templating.py", line 147, in render_template
    return _render(
  File "c:\users\t\appdata\local\programs\python\python38-32\lib\site-packages\flask\templating.py", line 128, in _render
    rv = template.render(context)
  File "c:\users\t\appdata\local\programs\python\python38-32\lib\site-packages\jinja2\environment.py", line 1304, in render
    self.environment.handle_exception()
  File "c:\users\t\appdata\local\programs\python\python38-32\lib\site-packages\jinja2\environment.py", line 925, in handle_exception
    raise rewrite_traceback_stack(source=source)
  File "C:\Users\T\Desktop\flask-GoodBrowserGames\app\templates\game.html", line 2, in top-level template code
    {% import 'bootstrap/wtf.html' as wtf %}
  File "C:\Users\T\Desktop\flask-GoodBrowserGames\app\templates\base.html", line 1, in top-level template code
    {% extends 'bootstrap/base.html' %}
  File "c:\users\t\appdata\local\programs\python\python38-32\lib\site-packages\flask_bootstrap\templates\bootstrap\base.html", line 1, in top-level template code
    {% block doc -%}
  File "c:\users\t\appdata\local\programs\python\python38-32\lib\site-packages\flask_bootstrap\templates\bootstrap\base.html", line 4, in block 'doc'
    {%- block html %}
  File "c:\users\t\appdata\local\programs\python\python38-32\lib\site-packages\flask_bootstrap\templates\bootstrap\base.html", line 20, in block 'html'
    {% block body -%}
  File "c:\users\t\appdata\local\programs\python\python38-32\lib\site-packages\flask_bootstrap\templates\bootstrap\base.html", line 23, in block 'body'
    {% block content -%}
  File "C:\Users\T\Desktop\flask-GoodBrowserGames\app\templates\base.html", line 55, in block 'content'
    {% block app_content %}{% endblock %}
  File "C:\Users\T\Desktop\flask-GoodBrowserGames\app\templates\game.html", line 10, in block 'app_content'
    {{ wtf.quick_form(review) }}
  File "c:\users\t\appdata\local\programs\python\python38-32\lib\site-packages\jinja2\runtime.py", line 828, in _invoke
    rv = self._func(*arguments)
  File "c:\users\t\appdata\local\programs\python\python38-32\lib\site-packages\flask_bootstrap\templates\bootstrap\wtf.html", line 200, in template
    {{ form.hidden_tag() }}
  File "c:\users\t\appdata\local\programs\python\python38-32\lib\site-packages\jinja2\environment.py", line 474, in getattr
    return getattr(obj, attribute)
jinja2.exceptions.UndefinedError: 'review' is undefined
2022-05-24 22:28:12,547 INFO: GoodBrowserGames startup [in C:\Users\T\Desktop\flask-GoodBrowserGames\app\__init__.py:82]
2022-05-24 22:33:02,503 INFO: GoodBrowserGames startup [in C:\Users\T\Desktop\flask-GoodBrowserGames\app\__init__.py:82]
2022-05-24 22:33:06,422 ERROR: Exception on /game/test [GET] [in c:\users\t\appdata\local\programs\python\python38-32\lib\site-packages\flask\app.py:1454]
Traceback (most recent call last):
  File "c:\users\t\appdata\local\programs\python\python38-32\lib\site-packages\flask\app.py", line 2070, in wsgi_app
    response = self.full_dispatch_request()
  File "c:\users\t\appdata\local\programs\python\python38-32\lib\site-packages\flask\app.py", line 1515, in full_dispatch_request
    rv = self.handle_user_exception(e)
  File "c:\users\t\appdata\local\programs\python\python38-32\lib\site-packages\flask\app.py", line 1513, in full_dispatch_request
    rv = self.dispatch_request()
  File "c:\users\t\appdata\local\programs\python\python38-32\lib\site-packages\flask\app.py", line 1499, in dispatch_request
    return self.ensure_sync(self.view_functions[rule.endpoint])(**req.view_args)
  File "c:\users\t\appdata\local\programs\python\python38-32\lib\site-packages\flask_login\utils.py", line 272, in decorated_view
    return func(*args, **kwargs)
  File "C:\Users\T\Desktop\flask-GoodBrowserGames\app\main\routes.py", line 206, in game
    reviews = game.reviews.order_by(Review.timestamp.desc()).paginate(
UnboundLocalError: local variable 'game' referenced before assignment
2022-05-24 22:33:38,461 INFO: GoodBrowserGames startup [in C:\Users\T\Desktop\flask-GoodBrowserGames\app\__init__.py:82]
2022-05-24 22:33:40,161 ERROR: Exception on /game/test [GET] [in c:\users\t\appdata\local\programs\python\python38-32\lib\site-packages\flask\app.py:1454]
Traceback (most recent call last):
  File "c:\users\t\appdata\local\programs\python\python38-32\lib\site-packages\flask\app.py", line 2070, in wsgi_app
    response = self.full_dispatch_request()
  File "c:\users\t\appdata\local\programs\python\python38-32\lib\site-packages\flask\app.py", line 1515, in full_dispatch_request
    rv = self.handle_user_exception(e)
  File "c:\users\t\appdata\local\programs\python\python38-32\lib\site-packages\flask\app.py", line 1513, in full_dispatch_request
    rv = self.dispatch_request()
  File "c:\users\t\appdata\local\programs\python\python38-32\lib\site-packages\flask\app.py", line 1499, in dispatch_request
    return self.ensure_sync(self.view_functions[rule.endpoint])(**req.view_args)
  File "c:\users\t\appdata\local\programs\python\python38-32\lib\site-packages\flask_login\utils.py", line 272, in decorated_view
    return func(*args, **kwargs)
  File "C:\Users\T\Desktop\flask-GoodBrowserGames\app\main\routes.py", line 206, in game
    reviews = game.reviews.order_by(Review.timestamp.desc()).paginate(
AttributeError: 'function' object has no attribute 'reviews'
2022-05-24 22:34:34,980 INFO: GoodBrowserGames startup [in C:\Users\T\Desktop\flask-GoodBrowserGames\app\__init__.py:82]
2022-05-24 22:36:16,410 INFO: GoodBrowserGames startup [in C:\Users\T\Desktop\flask-GoodBrowserGames\app\__init__.py:82]
2022-05-24 22:36:58,986 ERROR: Exception on /game/test [POST] [in c:\users\t\appdata\local\programs\python\python38-32\lib\site-packages\flask\app.py:1454]
Traceback (most recent call last):
  File "c:\users\t\appdata\local\programs\python\python38-32\lib\site-packages\flask\app.py", line 2070, in wsgi_app
    response = self.full_dispatch_request()
  File "c:\users\t\appdata\local\programs\python\python38-32\lib\site-packages\flask\app.py", line 1515, in full_dispatch_request
    rv = self.handle_user_exception(e)
  File "c:\users\t\appdata\local\programs\python\python38-32\lib\site-packages\flask\app.py", line 1513, in full_dispatch_request
    rv = self.dispatch_request()
  File "c:\users\t\appdata\local\programs\python\python38-32\lib\site-packages\flask\app.py", line 1499, in dispatch_request
    return self.ensure_sync(self.view_functions[rule.endpoint])(**req.view_args)
  File "c:\users\t\appdata\local\programs\python\python38-32\lib\site-packages\flask_login\utils.py", line 272, in decorated_view
    return func(*args, **kwargs)
  File "C:\Users\T\Desktop\flask-GoodBrowserGames\app\main\routes.py", line 205, in game
    return redirect(url_for('main.game'))
  File "c:\users\t\appdata\local\programs\python\python38-32\lib\site-packages\flask\helpers.py", line 338, in url_for
    return appctx.app.handle_url_build_error(error, endpoint, values)
  File "c:\users\t\appdata\local\programs\python\python38-32\lib\site-packages\flask\helpers.py", line 325, in url_for
    rv = url_adapter.build(
  File "c:\users\t\appdata\local\programs\python\python38-32\lib\site-packages\werkzeug\routing.py", line 2305, in build
    raise BuildError(endpoint, values, method, self)
werkzeug.routing.BuildError: Could not build url for endpoint 'main.game'. Did you forget to specify values ['name']?
2022-05-24 22:37:41,459 INFO: GoodBrowserGames startup [in C:\Users\T\Desktop\flask-GoodBrowserGames\app\__init__.py:82]
